[2023-10-30T21:57:53.227+0000] {taskinstance.py:1103} INFO - Dependencies all met for dep_context=non-requeueable deps ti=<TaskInstance: Extract_job_data_in_selenium_container.run_script_in_docker manual__2023-10-30T21:57:49.989567+00:00 [queued]>
[2023-10-30T21:57:53.249+0000] {taskinstance.py:1103} INFO - Dependencies all met for dep_context=requeueable deps ti=<TaskInstance: Extract_job_data_in_selenium_container.run_script_in_docker manual__2023-10-30T21:57:49.989567+00:00 [queued]>
[2023-10-30T21:57:53.250+0000] {taskinstance.py:1308} INFO - Starting attempt 1 of 2
[2023-10-30T21:57:53.274+0000] {taskinstance.py:1327} INFO - Executing <Task(DockerOperator): run_script_in_docker> on 2023-10-30 21:57:49.989567+00:00
[2023-10-30T21:57:53.283+0000] {standard_task_runner.py:57} INFO - Started process 3941 to run task
[2023-10-30T21:57:53.288+0000] {standard_task_runner.py:84} INFO - Running: ['***', 'tasks', 'run', 'Extract_job_data_in_selenium_container', 'run_script_in_docker', 'manual__2023-10-30T21:57:49.989567+00:00', '--job-id', '901', '--raw', '--subdir', 'DAGS_FOLDER/extract_job_data_dag.py', '--cfg-path', '/tmp/tmpcxru1x2c']
[2023-10-30T21:57:53.290+0000] {standard_task_runner.py:85} INFO - Job 901: Subtask run_script_in_docker
[2023-10-30T21:57:53.353+0000] {task_command.py:410} INFO - Running <TaskInstance: Extract_job_data_in_selenium_container.run_script_in_docker manual__2023-10-30T21:57:49.989567+00:00 [running]> on host 4be7b32a0cc0
[2023-10-30T21:57:53.476+0000] {taskinstance.py:1547} INFO - Exporting env vars: AIRFLOW_CTX_DAG_OWNER='***' AIRFLOW_CTX_DAG_ID='Extract_job_data_in_selenium_container' AIRFLOW_CTX_TASK_ID='run_script_in_docker' AIRFLOW_CTX_EXECUTION_DATE='2023-10-30T21:57:49.989567+00:00' AIRFLOW_CTX_TRY_NUMBER='1' AIRFLOW_CTX_DAG_RUN_ID='manual__2023-10-30T21:57:49.989567+00:00'
[2023-10-30T21:57:53.597+0000] {docker.py:334} INFO - Starting docker container from image webscrape-container
[2023-10-30T21:57:53.620+0000] {docker.py:343} WARNING - Using remote engine or docker-in-docker and mounting temporary volume from host is not supported. Falling back to `mount_tmp_dir=False` mode. You can set `mount_tmp_dir` parameter to False to disable mounting and remove the warning
[2023-10-30T21:57:55.395+0000] {docker.py:403} INFO - [9:54:1030/215755.394197:ERROR:bus.cc(407)] Failed to connect to the bus: Failed to connect to socket /var/run/dbus/system_bus_socket: No such file or directory
[2023-10-30T21:57:55.711+0000] {docker.py:403} INFO - [9:9:1030/215755.710183:ERROR:ozone_platform_x11.cc(239)] Missing X server or $DISPLAY
[9:9:1030/215755.710201:ERROR:env.cc(255)] The platform failed to initialize.  Exiting.
[2023-10-30T21:57:55.728+0000] {docker.py:403} INFO - [1030/215755.727218:ERROR:nacl_helper_linux.cc(354)] NaCl helper process running without a sandbox!
Most likely you need to configure your SUID sandbox correctly
[2023-10-30T21:57:57.314+0000] {docker.py:403} INFO - initialising bot
opening chrome (Linux)
open chrome
[2023-10-30T21:57:57.318+0000] {docker.py:403} INFO - Traceback (most recent call last):
  File "webscrape.py", line 158, in <module>
    StackScraper()
  File "webscrape.py", line 15, in __init__
    super().__init__(verbose=True)
  File "/tmp/Bot.py", line 56, in __init__
    self.driver = webdriver.Chrome(service=Service(),options=options)
  File "/usr/local/lib/python3.8/dist-packages/selenium/webdriver/chrome/webdriver.py", line 45, in __init__
    super().__init__(
  File "/usr/local/lib/python3.8/dist-packages/selenium/webdriver/chromium/webdriver.py", line 56, in __init__
    super().__init__(
  File "/usr/local/lib/python3.8/dist-packages/selenium/webdriver/remote/webdriver.py", line 205, in __init__
    self.start_session(capabilities)
  File "/usr/local/lib/python3.8/dist-packages/selenium/webdriver/remote/webdriver.py", line 289, in start_session
    response = self.execute(Command.NEW_SESSION, caps)["value"]
  File "/usr/local/lib/python3.8/dist-packages/selenium/webdriver/remote/webdriver.py", line 344, in execute
    self.error_handler.check_response(response)
  File "/usr/local/lib/python3.8/dist-packages/selenium/webdriver/remote/errorhandler.py", line 229, in check_response
    raise exception_class(message, screen, stacktrace)
selenium.common.exceptions.SessionNotCreatedException: Message: session not created: Chrome failed to start: exited normally.
  (session not created: DevToolsActivePort file doesn't exist)
  (The process started from chrome location /usr/bin/google-chrome is no longer running, so ChromeDriver is assuming that Chrome has crashed.)
Stacktrace:
#0 0x55a4070c0fb3 <unknown>
#1 0x55a406d944a7 <unknown>
#2 0x55a406dc7c93 <unknown>
#3 0x55a406dc410c <unknown>
#4 0x55a406e06ac6 <unknown>
#5 0x55a406dfd713 <unknown>
#6 0x55a406dd018b <unknown>
#7 0x55a406dd0f7e <unknown>
#8 0x55a4070868d8 <unknown>
#9 0x55a40708a800 <unknown>
#10 0x55a407094cfc <unknown>
#11 0x55a40708b418 <unknown>
#12 0x55a40705842f <unknown>
#13 0x55a4070af4e8 <unknown>
#14 0x55a4070af6b4 <unknown>
#15 0x55a4070c0143 <unknown>
#16 0x7f81da348609 start_thread
[2023-10-30T21:57:57.650+0000] {taskinstance.py:1824} ERROR - Task failed with exception
Traceback (most recent call last):
  File "/home/airflow/.local/lib/python3.7/site-packages/docker/api/client.py", line 268, in _raise_for_status
    response.raise_for_status()
  File "/home/airflow/.local/lib/python3.7/site-packages/requests/models.py", line 1021, in raise_for_status
    raise HTTPError(http_error_msg, response=self)
requests.exceptions.HTTPError: 400 Client Error: Bad Request for url: http://docker-proxy:2375/v1.43/containers/create

The above exception was the direct cause of the following exception:

Traceback (most recent call last):
  File "/home/airflow/.local/lib/python3.7/site-packages/airflow/providers/docker/operators/docker.py", line 339, in _run_image
    return self._run_image_with_mounts(self.mounts + [tmp_mount], add_tmp_variable=True)
  File "/home/airflow/.local/lib/python3.7/site-packages/airflow/providers/docker/operators/docker.py", line 393, in _run_image_with_mounts
    hostname=self.hostname,
  File "/home/airflow/.local/lib/python3.7/site-packages/docker/api/container.py", line 431, in create_container
    return self.create_container_from_config(config, name, platform)
  File "/home/airflow/.local/lib/python3.7/site-packages/docker/api/container.py", line 448, in create_container_from_config
    return self._result(res, True)
  File "/home/airflow/.local/lib/python3.7/site-packages/docker/api/client.py", line 274, in _result
    self._raise_for_status(response)
  File "/home/airflow/.local/lib/python3.7/site-packages/docker/api/client.py", line 270, in _raise_for_status
    raise create_api_error_from_http_exception(e) from e
  File "/home/airflow/.local/lib/python3.7/site-packages/docker/errors.py", line 39, in create_api_error_from_http_exception
    raise cls(e, response=response, explanation=explanation) from e
docker.errors.APIError: 400 Client Error for http://docker-proxy:2375/v1.43/containers/create: Bad Request ("invalid mount config for type "bind": bind source path does not exist: /tmp/airflowtmpy2k4y3y2")

During handling of the above exception, another exception occurred:

Traceback (most recent call last):
  File "/home/airflow/.local/lib/python3.7/site-packages/airflow/providers/docker/operators/docker.py", line 478, in execute
    return self._run_image()
  File "/home/airflow/.local/lib/python3.7/site-packages/airflow/providers/docker/operators/docker.py", line 348, in _run_image
    return self._run_image_with_mounts(self.mounts, add_tmp_variable=False)
  File "/home/airflow/.local/lib/python3.7/site-packages/airflow/providers/docker/operators/docker.py", line 412, in _run_image_with_mounts
    raise AirflowException(f"Docker container failed: {repr(result)} lines {joined_log_lines}")
airflow.exceptions.AirflowException: Docker container failed: {'StatusCode': 1} lines [9:54:1030/215755.394197:ERROR:bus.cc(407)] Failed to connect to the bus: Failed to connect to socket /var/run/dbus/system_bus_socket: No such file or directory
[9:9:1030/215755.710183:ERROR:ozone_platform_x11.cc(239)] Missing X server or $DISPLAY
[9:9:1030/215755.710201:ERROR:env.cc(255)] The platform failed to initialize.  Exiting.
[1030/215755.727218:ERROR:nacl_helper_linux.cc(354)] NaCl helper process running without a sandbox!
Most likely you need to configure your SUID sandbox correctly
initialising bot
opening chrome (Linux)
open chrome
Traceback (most recent call last):
  File "webscrape.py", line 158, in <module>
    StackScraper()
  File "webscrape.py", line 15, in __init__
    super().__init__(verbose=True)
  File "/tmp/Bot.py", line 56, in __init__
    self.driver = webdriver.Chrome(service=Service(),options=options)
  File "/usr/local/lib/python3.8/dist-packages/selenium/webdriver/chrome/webdriver.py", line 45, in __init__
    super().__init__(
  File "/usr/local/lib/python3.8/dist-packages/selenium/webdriver/chromium/webdriver.py", line 56, in __init__
    super().__init__(
  File "/usr/local/lib/python3.8/dist-packages/selenium/webdriver/remote/webdriver.py", line 205, in __init__
    self.start_session(capabilities)
  File "/usr/local/lib/python3.8/dist-packages/selenium/webdriver/remote/webdriver.py", line 289, in start_session
    response = self.execute(Command.NEW_SESSION, caps)["value"]
  File "/usr/local/lib/python3.8/dist-packages/selenium/webdriver/remote/webdriver.py", line 344, in execute
    self.error_handler.check_response(response)
  File "/usr/local/lib/python3.8/dist-packages/selenium/webdriver/remote/errorhandler.py", line 229, in check_response
    raise exception_class(message, screen, stacktrace)
selenium.common.exceptions.SessionNotCreatedException: Message: session not created: Chrome failed to start: exited normally.
  (session not created: DevToolsActivePort file doesn't exist)
  (The process started from chrome location /usr/bin/google-chrome is no longer running, so ChromeDriver is assuming that Chrome has crashed.)
Stacktrace:
#0 0x55a4070c0fb3 <unknown>
#1 0x55a406d944a7 <unknown>
#2 0x55a406dc7c93 <unknown>
#3 0x55a406dc410c <unknown>
#4 0x55a406e06ac6 <unknown>
#5 0x55a406dfd713 <unknown>
#6 0x55a406dd018b <unknown>
#7 0x55a406dd0f7e <unknown>
#8 0x55a4070868d8 <unknown>
#9 0x55a40708a800 <unknown>
#10 0x55a407094cfc <unknown>
#11 0x55a40708b418 <unknown>
#12 0x55a40705842f <unknown>
#13 0x55a4070af4e8 <unknown>
#14 0x55a4070af6b4 <unknown>
#15 0x55a4070c0143 <unknown>
#16 0x7f81da348609 start_thread
[2023-10-30T21:57:57.671+0000] {taskinstance.py:1350} INFO - Marking task as UP_FOR_RETRY. dag_id=Extract_job_data_in_selenium_container, task_id=run_script_in_docker, execution_date=20231030T215749, start_date=20231030T215753, end_date=20231030T215757
[2023-10-30T21:57:57.694+0000] {standard_task_runner.py:109} ERROR - Failed to execute job 901 for task run_script_in_docker (Docker container failed: {'StatusCode': 1} lines [9:54:1030/215755.394197:ERROR:bus.cc(407)] Failed to connect to the bus: Failed to connect to socket /var/run/dbus/system_bus_socket: No such file or directory
[9:9:1030/215755.710183:ERROR:ozone_platform_x11.cc(239)] Missing X server or $DISPLAY
[9:9:1030/215755.710201:ERROR:env.cc(255)] The platform failed to initialize.  Exiting.
[1030/215755.727218:ERROR:nacl_helper_linux.cc(354)] NaCl helper process running without a sandbox!
Most likely you need to configure your SUID sandbox correctly
initialising bot
opening chrome (Linux)
open chrome
Traceback (most recent call last):
  File "webscrape.py", line 158, in <module>
    StackScraper()
  File "webscrape.py", line 15, in __init__
    super().__init__(verbose=True)
  File "/tmp/Bot.py", line 56, in __init__
    self.driver = webdriver.Chrome(service=Service(),options=options)
  File "/usr/local/lib/python3.8/dist-packages/selenium/webdriver/chrome/webdriver.py", line 45, in __init__
    super().__init__(
  File "/usr/local/lib/python3.8/dist-packages/selenium/webdriver/chromium/webdriver.py", line 56, in __init__
    super().__init__(
  File "/usr/local/lib/python3.8/dist-packages/selenium/webdriver/remote/webdriver.py", line 205, in __init__
    self.start_session(capabilities)
  File "/usr/local/lib/python3.8/dist-packages/selenium/webdriver/remote/webdriver.py", line 289, in start_session
    response = self.execute(Command.NEW_SESSION, caps)["value"]
  File "/usr/local/lib/python3.8/dist-packages/selenium/webdriver/remote/webdriver.py", line 344, in execute
    self.error_handler.check_response(response)
  File "/usr/local/lib/python3.8/dist-packages/selenium/webdriver/remote/errorhandler.py", line 229, in check_response
    raise exception_class(message, screen, stacktrace)
selenium.common.exceptions.SessionNotCreatedException: Message: session not created: Chrome failed to start: exited normally.
  (session not created: DevToolsActivePort file doesn't exist)
  (The process started from chrome location /usr/bin/google-chrome is no longer running, so ChromeDriver is assuming that Chrome has crashed.)
Stacktrace:
#0 0x55a4070c0fb3 <unknown>
#1 0x55a406d944a7 <unknown>
#2 0x55a406dc7c93 <unknown>
#3 0x55a406dc410c <unknown>
#4 0x55a406e06ac6 <unknown>
#5 0x55a406dfd713 <unknown>
#6 0x55a406dd018b <unknown>
#7 0x55a406dd0f7e <unknown>
#8 0x55a4070868d8 <unknown>
#9 0x55a40708a800 <unknown>
#10 0x55a407094cfc <unknown>
#11 0x55a40708b418 <unknown>
#12 0x55a40705842f <unknown>
#13 0x55a4070af4e8 <unknown>
#14 0x55a4070af6b4 <unknown>
#15 0x55a4070c0143 <unknown>
#16 0x7f81da348609 start_thread; 3941)
[2023-10-30T21:57:57.723+0000] {local_task_job_runner.py:225} INFO - Task exited with return code 1
[2023-10-30T21:57:57.759+0000] {taskinstance.py:2653} INFO - 0 downstream tasks scheduled from follow-on schedule check
