[2023-11-02T20:21:54.349+0000] {taskinstance.py:1103} INFO - Dependencies all met for dep_context=non-requeueable deps ti=<TaskInstance: Google_Job_Listings_Data_Pipeline.run_script_in_docker manual__2023-11-02T20:21:52.140676+00:00 [queued]>
[2023-11-02T20:21:54.361+0000] {taskinstance.py:1103} INFO - Dependencies all met for dep_context=requeueable deps ti=<TaskInstance: Google_Job_Listings_Data_Pipeline.run_script_in_docker manual__2023-11-02T20:21:52.140676+00:00 [queued]>
[2023-11-02T20:21:54.362+0000] {taskinstance.py:1308} INFO - Starting attempt 1 of 2
[2023-11-02T20:21:54.380+0000] {taskinstance.py:1327} INFO - Executing <Task(DockerOperator): run_script_in_docker> on 2023-11-02 20:21:52.140676+00:00
[2023-11-02T20:21:54.393+0000] {standard_task_runner.py:57} INFO - Started process 283 to run task
[2023-11-02T20:21:54.401+0000] {standard_task_runner.py:84} INFO - Running: ['***', 'tasks', 'run', 'Google_Job_Listings_Data_Pipeline', 'run_script_in_docker', 'manual__2023-11-02T20:21:52.140676+00:00', '--job-id', '44', '--raw', '--subdir', 'DAGS_FOLDER/extract_job_data_dag.py', '--cfg-path', '/tmp/tmp8snf7u27']
[2023-11-02T20:21:54.402+0000] {standard_task_runner.py:85} INFO - Job 44: Subtask run_script_in_docker
[2023-11-02T20:21:54.459+0000] {task_command.py:410} INFO - Running <TaskInstance: Google_Job_Listings_Data_Pipeline.run_script_in_docker manual__2023-11-02T20:21:52.140676+00:00 [running]> on host 8443c9c4112a
[2023-11-02T20:21:54.554+0000] {taskinstance.py:1547} INFO - Exporting env vars: AIRFLOW_CTX_DAG_OWNER='***' AIRFLOW_CTX_DAG_ID='Google_Job_Listings_Data_Pipeline' AIRFLOW_CTX_TASK_ID='run_script_in_docker' AIRFLOW_CTX_EXECUTION_DATE='2023-11-02T20:21:52.140676+00:00' AIRFLOW_CTX_TRY_NUMBER='1' AIRFLOW_CTX_DAG_RUN_ID='manual__2023-11-02T20:21:52.140676+00:00'
[2023-11-02T20:21:55.731+0000] {taskinstance.py:1824} ERROR - Task failed with exception
Traceback (most recent call last):
  File "/home/airflow/.local/lib/python3.7/site-packages/urllib3/connection.py", line 175, in _new_conn
    (self._dns_host, self.port), self.timeout, **extra_kw
  File "/home/airflow/.local/lib/python3.7/site-packages/urllib3/util/connection.py", line 72, in create_connection
    for res in socket.getaddrinfo(host, port, family, socket.SOCK_STREAM):
  File "/usr/local/lib/python3.7/socket.py", line 752, in getaddrinfo
    for res in _socket.getaddrinfo(host, port, family, type, proto, flags):
socket.gaierror: [Errno -2] Name or service not known

During handling of the above exception, another exception occurred:

Traceback (most recent call last):
  File "/home/airflow/.local/lib/python3.7/site-packages/urllib3/connectionpool.py", line 721, in urlopen
    chunked=chunked,
  File "/home/airflow/.local/lib/python3.7/site-packages/urllib3/connectionpool.py", line 415, in _make_request
    conn.request(method, url, **httplib_request_kw)
  File "/home/airflow/.local/lib/python3.7/site-packages/urllib3/connection.py", line 244, in request
    super(HTTPConnection, self).request(method, url, body=body, headers=headers)
  File "/usr/local/lib/python3.7/http/client.py", line 1281, in request
    self._send_request(method, url, body, headers, encode_chunked)
  File "/usr/local/lib/python3.7/http/client.py", line 1327, in _send_request
    self.endheaders(body, encode_chunked=encode_chunked)
  File "/usr/local/lib/python3.7/http/client.py", line 1276, in endheaders
    self._send_output(message_body, encode_chunked=encode_chunked)
  File "/usr/local/lib/python3.7/http/client.py", line 1036, in _send_output
    self.send(msg)
  File "/usr/local/lib/python3.7/http/client.py", line 976, in send
    self.connect()
  File "/home/airflow/.local/lib/python3.7/site-packages/urllib3/connection.py", line 205, in connect
    conn = self._new_conn()
  File "/home/airflow/.local/lib/python3.7/site-packages/urllib3/connection.py", line 187, in _new_conn
    self, "Failed to establish a new connection: %s" % e
urllib3.exceptions.NewConnectionError: <urllib3.connection.HTTPConnection object at 0x7f1de9bc88d0>: Failed to establish a new connection: [Errno -2] Name or service not known

During handling of the above exception, another exception occurred:

Traceback (most recent call last):
  File "/home/airflow/.local/lib/python3.7/site-packages/requests/adapters.py", line 497, in send
    chunked=chunked,
  File "/home/airflow/.local/lib/python3.7/site-packages/urllib3/connectionpool.py", line 799, in urlopen
    method, url, error=e, _pool=self, _stacktrace=sys.exc_info()[2]
  File "/home/airflow/.local/lib/python3.7/site-packages/urllib3/util/retry.py", line 592, in increment
    raise MaxRetryError(_pool, url, error or ResponseError(cause))
urllib3.exceptions.MaxRetryError: HTTPConnectionPool(host='docker-proxy', port=2375): Max retries exceeded with url: /version (Caused by NewConnectionError('<urllib3.connection.HTTPConnection object at 0x7f1de9bc88d0>: Failed to establish a new connection: [Errno -2] Name or service not known'))

During handling of the above exception, another exception occurred:

Traceback (most recent call last):
  File "/home/airflow/.local/lib/python3.7/site-packages/docker/api/client.py", line 214, in _retrieve_server_version
    return self.version(api_version=False)["ApiVersion"]
  File "/home/airflow/.local/lib/python3.7/site-packages/docker/api/daemon.py", line 181, in version
    return self._result(self._get(url), json=True)
  File "/home/airflow/.local/lib/python3.7/site-packages/docker/utils/decorators.py", line 46, in inner
    return f(self, *args, **kwargs)
  File "/home/airflow/.local/lib/python3.7/site-packages/docker/api/client.py", line 237, in _get
    return self.get(url, **self._set_request_timeout(kwargs))
  File "/home/airflow/.local/lib/python3.7/site-packages/requests/sessions.py", line 602, in get
    return self.request("GET", url, **kwargs)
  File "/home/airflow/.local/lib/python3.7/site-packages/requests/sessions.py", line 589, in request
    resp = self.send(prep, **send_kwargs)
  File "/home/airflow/.local/lib/python3.7/site-packages/requests/sessions.py", line 703, in send
    r = adapter.send(request, **kwargs)
  File "/home/airflow/.local/lib/python3.7/site-packages/requests/adapters.py", line 519, in send
    raise ConnectionError(e, request=request)
requests.exceptions.ConnectionError: HTTPConnectionPool(host='docker-proxy', port=2375): Max retries exceeded with url: /version (Caused by NewConnectionError('<urllib3.connection.HTTPConnection object at 0x7f1de9bc88d0>: Failed to establish a new connection: [Errno -2] Name or service not known'))

During handling of the above exception, another exception occurred:

Traceback (most recent call last):
  File "/home/airflow/.local/lib/python3.7/site-packages/airflow/providers/docker/operators/docker.py", line 461, in execute
    if self.force_pull or not self.cli.images(name=self.image):
  File "/home/airflow/.local/lib/python3.7/site-packages/airflow/providers/docker/operators/docker.py", line 330, in cli
    return self.hook.api_client
  File "/home/airflow/.local/lib/python3.7/site-packages/cached_property.py", line 36, in __get__
    value = obj.__dict__[self.func.__name__] = self.func(obj)
  File "/home/airflow/.local/lib/python3.7/site-packages/airflow/providers/docker/hooks/docker.py", line 121, in api_client
    base_url=self.__base_url, version=self.__version, tls=self.__tls, timeout=self.__timeout
  File "/home/airflow/.local/lib/python3.7/site-packages/docker/api/client.py", line 197, in __init__
    self._version = self._retrieve_server_version()
  File "/home/airflow/.local/lib/python3.7/site-packages/docker/api/client.py", line 222, in _retrieve_server_version
    f'Error while fetching server API version: {e}'
docker.errors.DockerException: Error while fetching server API version: HTTPConnectionPool(host='docker-proxy', port=2375): Max retries exceeded with url: /version (Caused by NewConnectionError('<urllib3.connection.HTTPConnection object at 0x7f1de9bc88d0>: Failed to establish a new connection: [Errno -2] Name or service not known'))
[2023-11-02T20:21:55.765+0000] {taskinstance.py:1350} INFO - Marking task as UP_FOR_RETRY. dag_id=Google_Job_Listings_Data_Pipeline, task_id=run_script_in_docker, execution_date=20231102T202152, start_date=20231102T202154, end_date=20231102T202155
[2023-11-02T20:21:55.800+0000] {standard_task_runner.py:109} ERROR - Failed to execute job 44 for task run_script_in_docker (Error while fetching server API version: HTTPConnectionPool(host='docker-proxy', port=2375): Max retries exceeded with url: /version (Caused by NewConnectionError('<urllib3.connection.HTTPConnection object at 0x7f1de9bc88d0>: Failed to establish a new connection: [Errno -2] Name or service not known')); 283)
[2023-11-02T20:21:55.822+0000] {local_task_job_runner.py:225} INFO - Task exited with return code 1
[2023-11-02T20:21:55.861+0000] {taskinstance.py:2653} INFO - 0 downstream tasks scheduled from follow-on schedule check
