[2023-10-09T22:19:01.400+0000] {taskinstance.py:1103} INFO - Dependencies all met for dep_context=non-requeueable deps ti=<TaskInstance: Extract_job_data_in_selenium_container.upload_to_s3 manual__2023-10-09T22:12:32.848443+00:00 [queued]>
[2023-10-09T22:19:01.411+0000] {taskinstance.py:1103} INFO - Dependencies all met for dep_context=requeueable deps ti=<TaskInstance: Extract_job_data_in_selenium_container.upload_to_s3 manual__2023-10-09T22:12:32.848443+00:00 [queued]>
[2023-10-09T22:19:01.412+0000] {taskinstance.py:1308} INFO - Starting attempt 2 of 2
[2023-10-09T22:19:01.431+0000] {taskinstance.py:1327} INFO - Executing <Task(BashOperator): upload_to_s3> on 2023-10-09 22:12:32.848443+00:00
[2023-10-09T22:19:01.436+0000] {standard_task_runner.py:57} INFO - Started process 1389 to run task
[2023-10-09T22:19:01.440+0000] {standard_task_runner.py:84} INFO - Running: ['***', 'tasks', 'run', 'Extract_job_data_in_selenium_container', 'upload_to_s3', 'manual__2023-10-09T22:12:32.848443+00:00', '--job-id', '749', '--raw', '--subdir', 'DAGS_FOLDER/extract_job_data_dag.py', '--cfg-path', '/tmp/tmpn5ylpq42']
[2023-10-09T22:19:01.442+0000] {standard_task_runner.py:85} INFO - Job 749: Subtask upload_to_s3
[2023-10-09T22:19:01.533+0000] {task_command.py:410} INFO - Running <TaskInstance: Extract_job_data_in_selenium_container.upload_to_s3 manual__2023-10-09T22:12:32.848443+00:00 [running]> on host 18e533bd1f06
[2023-10-09T22:19:01.634+0000] {taskinstance.py:1547} INFO - Exporting env vars: AIRFLOW_CTX_DAG_OWNER='***' AIRFLOW_CTX_DAG_ID='Extract_job_data_in_selenium_container' AIRFLOW_CTX_TASK_ID='upload_to_s3' AIRFLOW_CTX_EXECUTION_DATE='2023-10-09T22:12:32.848443+00:00' AIRFLOW_CTX_TRY_NUMBER='2' AIRFLOW_CTX_DAG_RUN_ID='manual__2023-10-09T22:12:32.848443+00:00'
[2023-10-09T22:19:01.636+0000] {subprocess.py:63} INFO - Tmp dir root location: /tmp
[2023-10-09T22:19:01.637+0000] {subprocess.py:75} INFO - Running command: ['/bin/bash', '-c', 'python3 /opt/***/extraction/upload_aws_s3.py 20231009']
[2023-10-09T22:19:01.653+0000] {subprocess.py:86} INFO - Output:
[2023-10-09T22:19:12.485+0000] {subprocess.py:93} INFO - Traceback (most recent call last):
[2023-10-09T22:19:12.486+0000] {subprocess.py:93} INFO -   File "/home/***/.local/lib/python3.7/site-packages/boto3/s3/transfer.py", line 292, in upload_file
[2023-10-09T22:19:12.487+0000] {subprocess.py:93} INFO -     future.result()
[2023-10-09T22:19:12.488+0000] {subprocess.py:93} INFO -   File "/home/***/.local/lib/python3.7/site-packages/s3transfer/futures.py", line 103, in result
[2023-10-09T22:19:12.490+0000] {subprocess.py:93} INFO -     return self._coordinator.result()
[2023-10-09T22:19:12.491+0000] {subprocess.py:93} INFO -   File "/home/***/.local/lib/python3.7/site-packages/s3transfer/futures.py", line 266, in result
[2023-10-09T22:19:12.492+0000] {subprocess.py:93} INFO -     raise self._exception
[2023-10-09T22:19:12.493+0000] {subprocess.py:93} INFO -   File "/home/***/.local/lib/python3.7/site-packages/s3transfer/tasks.py", line 139, in __call__
[2023-10-09T22:19:12.493+0000] {subprocess.py:93} INFO -     return self._execute_main(kwargs)
[2023-10-09T22:19:12.494+0000] {subprocess.py:93} INFO -   File "/home/***/.local/lib/python3.7/site-packages/s3transfer/tasks.py", line 162, in _execute_main
[2023-10-09T22:19:12.494+0000] {subprocess.py:93} INFO -     return_value = self._main(**kwargs)
[2023-10-09T22:19:12.495+0000] {subprocess.py:93} INFO -   File "/home/***/.local/lib/python3.7/site-packages/s3transfer/upload.py", line 758, in _main
[2023-10-09T22:19:12.496+0000] {subprocess.py:93} INFO -     client.put_object(Bucket=bucket, Key=key, Body=body, **extra_args)
[2023-10-09T22:19:12.497+0000] {subprocess.py:93} INFO -   File "/home/***/.local/lib/python3.7/site-packages/botocore/client.py", line 530, in _api_call
[2023-10-09T22:19:12.497+0000] {subprocess.py:93} INFO -     return self._make_api_call(operation_name, kwargs)
[2023-10-09T22:19:12.498+0000] {subprocess.py:93} INFO -   File "/home/***/.local/lib/python3.7/site-packages/botocore/client.py", line 964, in _make_api_call
[2023-10-09T22:19:12.499+0000] {subprocess.py:93} INFO -     raise error_class(parsed_response, operation_name)
[2023-10-09T22:19:12.501+0000] {subprocess.py:93} INFO - botocore.exceptions.ClientError: An error occurred (InvalidAccessKeyId) when calling the PutObject operation: The AWS Access Key Id you provided does not exist in our records.
[2023-10-09T22:19:12.502+0000] {subprocess.py:93} INFO - 
[2023-10-09T22:19:12.503+0000] {subprocess.py:93} INFO - During handling of the above exception, another exception occurred:
[2023-10-09T22:19:12.504+0000] {subprocess.py:93} INFO - 
[2023-10-09T22:19:12.505+0000] {subprocess.py:93} INFO - Traceback (most recent call last):
[2023-10-09T22:19:12.506+0000] {subprocess.py:93} INFO -   File "/opt/***/extraction/upload_aws_s3.py", line 73, in <module>
[2023-10-09T22:19:12.507+0000] {subprocess.py:93} INFO -     main()
[2023-10-09T22:19:12.507+0000] {subprocess.py:93} INFO -   File "/opt/***/extraction/upload_aws_s3.py", line 36, in main
[2023-10-09T22:19:12.508+0000] {subprocess.py:93} INFO -     upload_file_to_s3(conn)
[2023-10-09T22:19:12.508+0000] {subprocess.py:93} INFO -   File "/opt/***/extraction/upload_aws_s3.py", line 68, in upload_file_to_s3
[2023-10-09T22:19:12.509+0000] {subprocess.py:93} INFO -     Filename="/tmp/" + FILENAME, Bucket=BUCKET_NAME, Key=KEY
[2023-10-09T22:19:12.510+0000] {subprocess.py:93} INFO -   File "/home/***/.local/lib/python3.7/site-packages/boto3/s3/inject.py", line 148, in upload_file
[2023-10-09T22:19:12.510+0000] {subprocess.py:93} INFO -     callback=Callback,
[2023-10-09T22:19:12.511+0000] {subprocess.py:93} INFO -   File "/home/***/.local/lib/python3.7/site-packages/boto3/s3/transfer.py", line 300, in upload_file
[2023-10-09T22:19:12.511+0000] {subprocess.py:93} INFO -     filename, '/'.join([bucket, key]), e
[2023-10-09T22:19:12.512+0000] {subprocess.py:93} INFO - boto3.exceptions.S3UploadFailedError: Failed to upload /tmp/20231009.csv to jobdata-bucket/20231009.csv: An error occurred (InvalidAccessKeyId) when calling the PutObject operation: The AWS Access Key Id you provided does not exist in our records.
[2023-10-09T22:19:12.601+0000] {subprocess.py:97} INFO - Command exited with return code 1
[2023-10-09T22:19:12.623+0000] {taskinstance.py:1824} ERROR - Task failed with exception
Traceback (most recent call last):
  File "/home/airflow/.local/lib/python3.7/site-packages/airflow/operators/bash.py", line 211, in execute
    f"Bash command failed. The command returned a non-zero exit code {result.exit_code}."
airflow.exceptions.AirflowException: Bash command failed. The command returned a non-zero exit code 1.
[2023-10-09T22:19:12.630+0000] {taskinstance.py:1350} INFO - Marking task as FAILED. dag_id=Extract_job_data_in_selenium_container, task_id=upload_to_s3, execution_date=20231009T221232, start_date=20231009T221901, end_date=20231009T221912
[2023-10-09T22:19:12.657+0000] {standard_task_runner.py:109} ERROR - Failed to execute job 749 for task upload_to_s3 (Bash command failed. The command returned a non-zero exit code 1.; 1389)
[2023-10-09T22:19:12.706+0000] {local_task_job_runner.py:225} INFO - Task exited with return code 1
[2023-10-09T22:19:12.736+0000] {taskinstance.py:2653} INFO - 0 downstream tasks scheduled from follow-on schedule check
