[2023-10-10T00:54:18.911+0000] {taskinstance.py:1103} INFO - Dependencies all met for dep_context=non-requeueable deps ti=<TaskInstance: Extract_job_data_in_selenium_container.upload_to_s3 manual__2023-10-10T00:48:15.201367+00:00 [queued]>
[2023-10-10T00:54:18.923+0000] {taskinstance.py:1103} INFO - Dependencies all met for dep_context=requeueable deps ti=<TaskInstance: Extract_job_data_in_selenium_container.upload_to_s3 manual__2023-10-10T00:48:15.201367+00:00 [queued]>
[2023-10-10T00:54:18.923+0000] {taskinstance.py:1308} INFO - Starting attempt 2 of 2
[2023-10-10T00:54:18.943+0000] {taskinstance.py:1327} INFO - Executing <Task(BashOperator): upload_to_s3> on 2023-10-10 00:48:15.201367+00:00
[2023-10-10T00:54:18.948+0000] {standard_task_runner.py:57} INFO - Started process 4214 to run task
[2023-10-10T00:54:18.952+0000] {standard_task_runner.py:84} INFO - Running: ['***', 'tasks', 'run', 'Extract_job_data_in_selenium_container', 'upload_to_s3', 'manual__2023-10-10T00:48:15.201367+00:00', '--job-id', '770', '--raw', '--subdir', 'DAGS_FOLDER/extract_job_data_dag.py', '--cfg-path', '/tmp/tmp1zj4e7vo']
[2023-10-10T00:54:18.953+0000] {standard_task_runner.py:85} INFO - Job 770: Subtask upload_to_s3
[2023-10-10T00:54:19.011+0000] {task_command.py:410} INFO - Running <TaskInstance: Extract_job_data_in_selenium_container.upload_to_s3 manual__2023-10-10T00:48:15.201367+00:00 [running]> on host 18e533bd1f06
[2023-10-10T00:54:19.098+0000] {taskinstance.py:1547} INFO - Exporting env vars: AIRFLOW_CTX_DAG_OWNER='***' AIRFLOW_CTX_DAG_ID='Extract_job_data_in_selenium_container' AIRFLOW_CTX_TASK_ID='upload_to_s3' AIRFLOW_CTX_EXECUTION_DATE='2023-10-10T00:48:15.201367+00:00' AIRFLOW_CTX_TRY_NUMBER='2' AIRFLOW_CTX_DAG_RUN_ID='manual__2023-10-10T00:48:15.201367+00:00'
[2023-10-10T00:54:19.100+0000] {subprocess.py:63} INFO - Tmp dir root location: /tmp
[2023-10-10T00:54:19.101+0000] {subprocess.py:75} INFO - Running command: ['/bin/bash', '-c', 'python3 /opt/***/extraction/upload_aws_s3.py 20231010']
[2023-10-10T00:54:19.114+0000] {subprocess.py:86} INFO - Output:
[2023-10-10T00:54:30.920+0000] {subprocess.py:93} INFO - Traceback (most recent call last):
[2023-10-10T00:54:30.922+0000] {subprocess.py:93} INFO -   File "/home/***/.local/lib/python3.7/site-packages/boto3/s3/transfer.py", line 292, in upload_file
[2023-10-10T00:54:30.924+0000] {subprocess.py:93} INFO -     future.result()
[2023-10-10T00:54:30.926+0000] {subprocess.py:93} INFO -   File "/home/***/.local/lib/python3.7/site-packages/s3transfer/futures.py", line 103, in result
[2023-10-10T00:54:30.927+0000] {subprocess.py:93} INFO -     return self._coordinator.result()
[2023-10-10T00:54:30.928+0000] {subprocess.py:93} INFO -   File "/home/***/.local/lib/python3.7/site-packages/s3transfer/futures.py", line 266, in result
[2023-10-10T00:54:30.929+0000] {subprocess.py:93} INFO -     raise self._exception
[2023-10-10T00:54:30.930+0000] {subprocess.py:93} INFO -   File "/home/***/.local/lib/python3.7/site-packages/s3transfer/tasks.py", line 139, in __call__
[2023-10-10T00:54:30.930+0000] {subprocess.py:93} INFO -     return self._execute_main(kwargs)
[2023-10-10T00:54:30.931+0000] {subprocess.py:93} INFO -   File "/home/***/.local/lib/python3.7/site-packages/s3transfer/tasks.py", line 162, in _execute_main
[2023-10-10T00:54:30.932+0000] {subprocess.py:93} INFO -     return_value = self._main(**kwargs)
[2023-10-10T00:54:30.932+0000] {subprocess.py:93} INFO -   File "/home/***/.local/lib/python3.7/site-packages/s3transfer/upload.py", line 758, in _main
[2023-10-10T00:54:30.933+0000] {subprocess.py:93} INFO -     client.put_object(Bucket=bucket, Key=key, Body=body, **extra_args)
[2023-10-10T00:54:30.934+0000] {subprocess.py:93} INFO -   File "/home/***/.local/lib/python3.7/site-packages/botocore/client.py", line 530, in _api_call
[2023-10-10T00:54:30.934+0000] {subprocess.py:93} INFO -     return self._make_api_call(operation_name, kwargs)
[2023-10-10T00:54:30.935+0000] {subprocess.py:93} INFO -   File "/home/***/.local/lib/python3.7/site-packages/botocore/client.py", line 964, in _make_api_call
[2023-10-10T00:54:30.935+0000] {subprocess.py:93} INFO -     raise error_class(parsed_response, operation_name)
[2023-10-10T00:54:30.936+0000] {subprocess.py:93} INFO - botocore.exceptions.ClientError: An error occurred (InvalidAccessKeyId) when calling the PutObject operation: The AWS Access Key Id you provided does not exist in our records.
[2023-10-10T00:54:30.937+0000] {subprocess.py:93} INFO - 
[2023-10-10T00:54:30.937+0000] {subprocess.py:93} INFO - During handling of the above exception, another exception occurred:
[2023-10-10T00:54:30.938+0000] {subprocess.py:93} INFO - 
[2023-10-10T00:54:30.938+0000] {subprocess.py:93} INFO - Traceback (most recent call last):
[2023-10-10T00:54:30.939+0000] {subprocess.py:93} INFO -   File "/opt/***/extraction/upload_aws_s3.py", line 73, in <module>
[2023-10-10T00:54:30.939+0000] {subprocess.py:93} INFO -     main()
[2023-10-10T00:54:30.939+0000] {subprocess.py:93} INFO -   File "/opt/***/extraction/upload_aws_s3.py", line 36, in main
[2023-10-10T00:54:30.940+0000] {subprocess.py:93} INFO -     upload_file_to_s3(conn)
[2023-10-10T00:54:30.940+0000] {subprocess.py:93} INFO -   File "/opt/***/extraction/upload_aws_s3.py", line 68, in upload_file_to_s3
[2023-10-10T00:54:30.941+0000] {subprocess.py:93} INFO -     Filename="/tmp/" + FILENAME, Bucket=BUCKET_NAME, Key=KEY
[2023-10-10T00:54:30.941+0000] {subprocess.py:93} INFO -   File "/home/***/.local/lib/python3.7/site-packages/boto3/s3/inject.py", line 148, in upload_file
[2023-10-10T00:54:30.941+0000] {subprocess.py:93} INFO -     callback=Callback,
[2023-10-10T00:54:30.942+0000] {subprocess.py:93} INFO -   File "/home/***/.local/lib/python3.7/site-packages/boto3/s3/transfer.py", line 300, in upload_file
[2023-10-10T00:54:30.942+0000] {subprocess.py:93} INFO -     filename, '/'.join([bucket, key]), e
[2023-10-10T00:54:30.943+0000] {subprocess.py:93} INFO - boto3.exceptions.S3UploadFailedError: Failed to upload /tmp/20231010.csv to jobdata-bucket/20231010.csv: An error occurred (InvalidAccessKeyId) when calling the PutObject operation: The AWS Access Key Id you provided does not exist in our records.
[2023-10-10T00:54:31.030+0000] {subprocess.py:97} INFO - Command exited with return code 1
[2023-10-10T00:54:31.052+0000] {taskinstance.py:1824} ERROR - Task failed with exception
Traceback (most recent call last):
  File "/home/airflow/.local/lib/python3.7/site-packages/airflow/operators/bash.py", line 211, in execute
    f"Bash command failed. The command returned a non-zero exit code {result.exit_code}."
airflow.exceptions.AirflowException: Bash command failed. The command returned a non-zero exit code 1.
[2023-10-10T00:54:31.058+0000] {taskinstance.py:1350} INFO - Marking task as FAILED. dag_id=Extract_job_data_in_selenium_container, task_id=upload_to_s3, execution_date=20231010T004815, start_date=20231010T005418, end_date=20231010T005431
[2023-10-10T00:54:31.093+0000] {standard_task_runner.py:109} ERROR - Failed to execute job 770 for task upload_to_s3 (Bash command failed. The command returned a non-zero exit code 1.; 4214)
[2023-10-10T00:54:31.105+0000] {local_task_job_runner.py:225} INFO - Task exited with return code 1
[2023-10-10T00:54:31.123+0000] {taskinstance.py:2653} INFO - 0 downstream tasks scheduled from follow-on schedule check
