[2023-10-09T02:13:50.379+0000] {taskinstance.py:1103} INFO - Dependencies all met for dep_context=non-requeueable deps ti=<TaskInstance: Extract_job_data_in_selenium_container.run_script_in_docker manual__2023-10-09T02:13:48.237144+00:00 [queued]>
[2023-10-09T02:13:50.394+0000] {taskinstance.py:1103} INFO - Dependencies all met for dep_context=requeueable deps ti=<TaskInstance: Extract_job_data_in_selenium_container.run_script_in_docker manual__2023-10-09T02:13:48.237144+00:00 [queued]>
[2023-10-09T02:13:50.394+0000] {taskinstance.py:1308} INFO - Starting attempt 1 of 2
[2023-10-09T02:13:50.418+0000] {taskinstance.py:1327} INFO - Executing <Task(DockerOperator): run_script_in_docker> on 2023-10-09 02:13:48.237144+00:00
[2023-10-09T02:13:50.427+0000] {standard_task_runner.py:57} INFO - Started process 81 to run task
[2023-10-09T02:13:50.430+0000] {standard_task_runner.py:84} INFO - Running: ['***', 'tasks', 'run', 'Extract_job_data_in_selenium_container', 'run_script_in_docker', 'manual__2023-10-09T02:13:48.237144+00:00', '--job-id', '607', '--raw', '--subdir', 'DAGS_FOLDER/extract_job_data_dag.py', '--cfg-path', '/tmp/tmpfe9zje0u']
[2023-10-09T02:13:50.432+0000] {standard_task_runner.py:85} INFO - Job 607: Subtask run_script_in_docker
[2023-10-09T02:13:50.523+0000] {task_command.py:410} INFO - Running <TaskInstance: Extract_job_data_in_selenium_container.run_script_in_docker manual__2023-10-09T02:13:48.237144+00:00 [running]> on host e12c8be37a23
[2023-10-09T02:13:50.670+0000] {taskinstance.py:1547} INFO - Exporting env vars: AIRFLOW_CTX_DAG_OWNER='***' AIRFLOW_CTX_DAG_ID='Extract_job_data_in_selenium_container' AIRFLOW_CTX_TASK_ID='run_script_in_docker' AIRFLOW_CTX_EXECUTION_DATE='2023-10-09T02:13:48.237144+00:00' AIRFLOW_CTX_TRY_NUMBER='1' AIRFLOW_CTX_DAG_RUN_ID='manual__2023-10-09T02:13:48.237144+00:00'
[2023-10-09T02:13:50.710+0000] {docker.py:334} INFO - Starting docker container from image webscrape-container
[2023-10-09T02:13:50.721+0000] {docker.py:343} WARNING - Using remote engine or docker-in-docker and mounting temporary volume from host is not supported. Falling back to `mount_tmp_dir=False` mode. You can set `mount_tmp_dir` parameter to False to disable mounting and remove the warning
[2023-10-09T02:13:51.170+0000] {docker.py:403} INFO - python3: can't open file 'webscrape.py': [Errno 2] No such file or directory
[2023-10-09T02:13:51.347+0000] {taskinstance.py:1824} ERROR - Task failed with exception
Traceback (most recent call last):
  File "/home/airflow/.local/lib/python3.7/site-packages/docker/api/client.py", line 268, in _raise_for_status
    response.raise_for_status()
  File "/home/airflow/.local/lib/python3.7/site-packages/requests/models.py", line 1021, in raise_for_status
    raise HTTPError(http_error_msg, response=self)
requests.exceptions.HTTPError: 400 Client Error: Bad Request for url: http://docker-proxy:2375/v1.43/containers/create

The above exception was the direct cause of the following exception:

Traceback (most recent call last):
  File "/home/airflow/.local/lib/python3.7/site-packages/airflow/providers/docker/operators/docker.py", line 339, in _run_image
    return self._run_image_with_mounts(self.mounts + [tmp_mount], add_tmp_variable=True)
  File "/home/airflow/.local/lib/python3.7/site-packages/airflow/providers/docker/operators/docker.py", line 393, in _run_image_with_mounts
    hostname=self.hostname,
  File "/home/airflow/.local/lib/python3.7/site-packages/docker/api/container.py", line 431, in create_container
    return self.create_container_from_config(config, name, platform)
  File "/home/airflow/.local/lib/python3.7/site-packages/docker/api/container.py", line 448, in create_container_from_config
    return self._result(res, True)
  File "/home/airflow/.local/lib/python3.7/site-packages/docker/api/client.py", line 274, in _result
    self._raise_for_status(response)
  File "/home/airflow/.local/lib/python3.7/site-packages/docker/api/client.py", line 270, in _raise_for_status
    raise create_api_error_from_http_exception(e) from e
  File "/home/airflow/.local/lib/python3.7/site-packages/docker/errors.py", line 39, in create_api_error_from_http_exception
    raise cls(e, response=response, explanation=explanation) from e
docker.errors.APIError: 400 Client Error for http://docker-proxy:2375/v1.43/containers/create: Bad Request ("invalid mount config for type "bind": bind source path does not exist: /tmp/airflowtmp2cbgl4hq")

During handling of the above exception, another exception occurred:

Traceback (most recent call last):
  File "/home/airflow/.local/lib/python3.7/site-packages/airflow/providers/docker/operators/docker.py", line 478, in execute
    return self._run_image()
  File "/home/airflow/.local/lib/python3.7/site-packages/airflow/providers/docker/operators/docker.py", line 348, in _run_image
    return self._run_image_with_mounts(self.mounts, add_tmp_variable=False)
  File "/home/airflow/.local/lib/python3.7/site-packages/airflow/providers/docker/operators/docker.py", line 412, in _run_image_with_mounts
    raise AirflowException(f"Docker container failed: {repr(result)} lines {joined_log_lines}")
airflow.exceptions.AirflowException: Docker container failed: {'StatusCode': 2} lines python3: can't open file 'webscrape.py': [Errno 2] No such file or directory
[2023-10-09T02:13:51.361+0000] {taskinstance.py:1350} INFO - Marking task as UP_FOR_RETRY. dag_id=Extract_job_data_in_selenium_container, task_id=run_script_in_docker, execution_date=20231009T021348, start_date=20231009T021350, end_date=20231009T021351
[2023-10-09T02:13:51.379+0000] {standard_task_runner.py:109} ERROR - Failed to execute job 607 for task run_script_in_docker (Docker container failed: {'StatusCode': 2} lines python3: can't open file 'webscrape.py': [Errno 2] No such file or directory; 81)
[2023-10-09T02:13:51.406+0000] {local_task_job_runner.py:225} INFO - Task exited with return code 1
[2023-10-09T02:13:51.426+0000] {taskinstance.py:2653} INFO - 0 downstream tasks scheduled from follow-on schedule check
