[2023-10-23T21:09:50.440+0000] {taskinstance.py:1103} INFO - Dependencies all met for dep_context=non-requeueable deps ti=<TaskInstance: Extract_job_data_in_selenium_container.run_script_in_docker manual__2023-10-23T21:09:47.659732+00:00 [queued]>
[2023-10-23T21:09:50.458+0000] {taskinstance.py:1103} INFO - Dependencies all met for dep_context=requeueable deps ti=<TaskInstance: Extract_job_data_in_selenium_container.run_script_in_docker manual__2023-10-23T21:09:47.659732+00:00 [queued]>
[2023-10-23T21:09:50.458+0000] {taskinstance.py:1308} INFO - Starting attempt 1 of 2
[2023-10-23T21:09:50.478+0000] {taskinstance.py:1327} INFO - Executing <Task(DockerOperator): run_script_in_docker> on 2023-10-23 21:09:47.659732+00:00
[2023-10-23T21:09:50.484+0000] {standard_task_runner.py:57} INFO - Started process 154 to run task
[2023-10-23T21:09:50.489+0000] {standard_task_runner.py:84} INFO - Running: ['***', 'tasks', 'run', 'Extract_job_data_in_selenium_container', 'run_script_in_docker', 'manual__2023-10-23T21:09:47.659732+00:00', '--job-id', '819', '--raw', '--subdir', 'DAGS_FOLDER/extract_job_data_dag.py', '--cfg-path', '/tmp/tmp4lkikink']
[2023-10-23T21:09:50.490+0000] {standard_task_runner.py:85} INFO - Job 819: Subtask run_script_in_docker
[2023-10-23T21:09:50.551+0000] {task_command.py:410} INFO - Running <TaskInstance: Extract_job_data_in_selenium_container.run_script_in_docker manual__2023-10-23T21:09:47.659732+00:00 [running]> on host 4be7b32a0cc0
[2023-10-23T21:09:50.653+0000] {taskinstance.py:1547} INFO - Exporting env vars: AIRFLOW_CTX_DAG_OWNER='***' AIRFLOW_CTX_DAG_ID='Extract_job_data_in_selenium_container' AIRFLOW_CTX_TASK_ID='run_script_in_docker' AIRFLOW_CTX_EXECUTION_DATE='2023-10-23T21:09:47.659732+00:00' AIRFLOW_CTX_TRY_NUMBER='1' AIRFLOW_CTX_DAG_RUN_ID='manual__2023-10-23T21:09:47.659732+00:00'
[2023-10-23T21:09:50.687+0000] {docker.py:334} INFO - Starting docker container from image webscrape-container
[2023-10-23T21:09:50.708+0000] {docker.py:343} WARNING - Using remote engine or docker-in-docker and mounting temporary volume from host is not supported. Falling back to `mount_tmp_dir=False` mode. You can set `mount_tmp_dir` parameter to False to disable mounting and remove the warning
[2023-10-23T21:09:53.442+0000] {docker.py:403} INFO - [13:60:1023/210953.441311:ERROR:bus.cc(406)] Failed to connect to the bus: Failed to connect to socket /var/run/dbus/system_bus_socket: No such file or directory
[2023-10-23T21:09:53.655+0000] {docker.py:403} INFO - [13:63:1023/210953.655031:ERROR:bus.cc(406)] Failed to connect to the bus: Failed to connect to socket /var/run/dbus/system_bus_socket: No such file or directory
[13:63:1023/210953.655072:ERROR:bus.cc(406)] Failed to connect to the bus: Failed to connect to socket /var/run/dbus/system_bus_socket: No such file or directory
[2023-10-23T21:09:53.664+0000] {docker.py:403} INFO - [13:60:1023/210953.663656:ERROR:bus.cc(406)] Failed to connect to the bus: Could not parse server address: Unknown address type (examples of valid types are "tcp" and on UNIX "unix")
[2023-10-23T21:09:53.665+0000] {docker.py:403} INFO - [13:60:1023/210953.663728:ERROR:bus.cc(406)] Failed to connect to the bus: Could not parse server address: Unknown address type (examples of valid types are "tcp" and on UNIX "unix")
[13:60:1023/210953.663743:ERROR:bus.cc(406)] Failed to connect to the bus: Could not parse server address: Unknown address type (examples of valid types are "tcp" and on UNIX "unix")
[13:60:1023/210953.663752:ERROR:bus.cc(406)] Failed to connect to the bus: Could not parse server address: Unknown address type (examples of valid types are "tcp" and on UNIX "unix")
[2023-10-23T21:09:53.705+0000] {docker.py:403} INFO - [13:60:1023/210953.704933:ERROR:bus.cc(406)] Failed to connect to the bus: Could not parse server address: Unknown address type (examples of valid types are "tcp" and on UNIX "unix")
[13:60:1023/210953.704965:ERROR:bus.cc(406)] Failed to connect to the bus: Could not parse server address: Unknown address type (examples of valid types are "tcp" and on UNIX "unix")
[2023-10-23T21:09:53.776+0000] {docker.py:403} INFO - DevTools listening on ws://127.0.0.1:4444/devtools/browser/78a38890-8e28-4a91-8d8c-a202d27bd468
[2023-10-23T21:09:53.809+0000] {docker.py:403} INFO - [13:13:1023/210953.808703:ERROR:object_proxy.cc(576)] Failed to call method: org.freedesktop.portal.Settings.Read: object_path= /org/freedesktop/portal/desktop: unknown error type:
[2023-10-23T21:09:53.828+0000] {docker.py:403} INFO - [13:101:1023/210953.827554:ERROR:bus.cc(406)] Failed to connect to the bus: Failed to connect to socket /var/run/dbus/system_bus_socket: No such file or directory
[2023-10-23T21:09:53.829+0000] {docker.py:403} INFO - [13:101:1023/210953.828004:ERROR:bus.cc(406)] Failed to connect to the bus: Failed to connect to socket /var/run/dbus/system_bus_socket: No such file or directory
[2023-10-23T21:09:53.830+0000] {docker.py:403} INFO - [13:101:1023/210953.828297:ERROR:bus.cc(406)] Failed to connect to the bus: Failed to connect to socket /var/run/dbus/system_bus_socket: No such file or directory
[13:101:1023/210953.828480:ERROR:bus.cc(406)] Failed to connect to the bus: Failed to connect to socket /var/run/dbus/system_bus_socket: No such file or directory
[13:101:1023/210953.828712:ERROR:bus.cc(406)] Failed to connect to the bus: Failed to connect to socket /var/run/dbus/system_bus_socket: No such file or directory
[2023-10-23T21:09:53.939+0000] {docker.py:403} INFO - [74:74:1023/210953.936927:ERROR:viz_main_impl.cc(196)] Exiting GPU process due to errors during initialization
[2023-10-23T21:13:36.039+0000] {taskinstance.py:1350} INFO - Marking task as SUCCESS. dag_id=Extract_job_data_in_selenium_container, task_id=run_script_in_docker, execution_date=20231023T210947, start_date=20231023T210950, end_date=20231023T211336
[2023-10-23T21:13:36.072+0000] {local_task_job_runner.py:225} INFO - Task exited with return code 0
[2023-10-23T21:13:36.110+0000] {taskinstance.py:2653} INFO - 1 downstream tasks scheduled from follow-on schedule check
