[2023-10-08T21:42:16.364+0000] {taskinstance.py:1103} INFO - Dependencies all met for dep_context=non-requeueable deps ti=<TaskInstance: Extract_job_data_in_selenium_container.run_script_in_docker manual__2023-10-08T21:42:14.805759+00:00 [queued]>
[2023-10-08T21:42:16.389+0000] {taskinstance.py:1103} INFO - Dependencies all met for dep_context=requeueable deps ti=<TaskInstance: Extract_job_data_in_selenium_container.run_script_in_docker manual__2023-10-08T21:42:14.805759+00:00 [queued]>
[2023-10-08T21:42:16.390+0000] {taskinstance.py:1308} INFO - Starting attempt 1 of 2
[2023-10-08T21:42:16.438+0000] {taskinstance.py:1327} INFO - Executing <Task(DockerOperator): run_script_in_docker> on 2023-10-08 21:42:14.805759+00:00
[2023-10-08T21:42:16.449+0000] {standard_task_runner.py:57} INFO - Started process 875 to run task
[2023-10-08T21:42:16.458+0000] {standard_task_runner.py:84} INFO - Running: ['***', 'tasks', 'run', 'Extract_job_data_in_selenium_container', 'run_script_in_docker', 'manual__2023-10-08T21:42:14.805759+00:00', '--job-id', '521', '--raw', '--subdir', 'DAGS_FOLDER/extract_job_data_dag.py', '--cfg-path', '/tmp/tmp83uxb54e']
[2023-10-08T21:42:16.461+0000] {standard_task_runner.py:85} INFO - Job 521: Subtask run_script_in_docker
[2023-10-08T21:42:16.576+0000] {task_command.py:410} INFO - Running <TaskInstance: Extract_job_data_in_selenium_container.run_script_in_docker manual__2023-10-08T21:42:14.805759+00:00 [running]> on host cae9180efd34
[2023-10-08T21:42:16.714+0000] {taskinstance.py:1547} INFO - Exporting env vars: AIRFLOW_CTX_DAG_OWNER='***' AIRFLOW_CTX_DAG_ID='Extract_job_data_in_selenium_container' AIRFLOW_CTX_TASK_ID='run_script_in_docker' AIRFLOW_CTX_EXECUTION_DATE='2023-10-08T21:42:14.805759+00:00' AIRFLOW_CTX_TRY_NUMBER='1' AIRFLOW_CTX_DAG_RUN_ID='manual__2023-10-08T21:42:14.805759+00:00'
[2023-10-08T21:42:16.739+0000] {docker.py:334} INFO - Starting docker container from image ***-webscrape-container
[2023-10-08T21:42:16.748+0000] {docker.py:343} WARNING - Using remote engine or docker-in-docker and mounting temporary volume from host is not supported. Falling back to `mount_tmp_dir=False` mode. You can set `mount_tmp_dir` parameter to False to disable mounting and remove the warning
[2023-10-08T21:42:17.682+0000] {docker.py:403} INFO - [13:60:1008/214217.681363:ERROR:bus.cc(406)] Failed to connect to the bus: Failed to connect to socket /var/run/dbus/system_bus_socket: No such file or directory
[2023-10-08T21:42:17.854+0000] {docker.py:403} INFO - [13:64:1008/214217.853438:ERROR:bus.cc(406)] Failed to connect to the bus: Failed to connect to socket /var/run/dbus/system_bus_socket: No such file or directory
[13:64:1008/214217.853514:ERROR:bus.cc(406)] Failed to connect to the bus: Failed to connect to socket /var/run/dbus/system_bus_socket: No such file or directory
[2023-10-08T21:42:17.857+0000] {docker.py:403} INFO - [13:60:1008/214217.857145:ERROR:bus.cc(406)] Failed to connect to the bus: Could not parse server address: Unknown address type (examples of valid types are "tcp" and on UNIX "unix")
[13:60:1008/214217.857224:ERROR:bus.cc(406)] Failed to connect to the bus: Could not parse server address: Unknown address type (examples of valid types are "tcp" and on UNIX "unix")
[2023-10-08T21:42:17.858+0000] {docker.py:403} INFO - [13:60:1008/214217.857241:ERROR:bus.cc(406)] Failed to connect to the bus: Could not parse server address: Unknown address type (examples of valid types are "tcp" and on UNIX "unix")
[13:60:1008/214217.857250:ERROR:bus.cc(406)] Failed to connect to the bus: Could not parse server address: Unknown address type (examples of valid types are "tcp" and on UNIX "unix")
[2023-10-08T21:42:17.875+0000] {docker.py:403} INFO - [13:60:1008/214217.874034:ERROR:bus.cc(406)] Failed to connect to the bus: Could not parse server address: Unknown address type (examples of valid types are "tcp" and on UNIX "unix")
[13:60:1008/214217.874071:ERROR:bus.cc(406)] Failed to connect to the bus: Could not parse server address: Unknown address type (examples of valid types are "tcp" and on UNIX "unix")
[2023-10-08T21:42:17.892+0000] {docker.py:403} INFO - DevTools listening on ws://127.0.0.1:4444/devtools/browser/c340d8be-c42e-4fb7-b992-af066ec370fc
[2023-10-08T21:42:17.909+0000] {docker.py:403} INFO - [13:13:1008/214217.908514:ERROR:object_proxy.cc(576)] Failed to call method: org.freedesktop.portal.Settings.Read: object_path= /org/freedesktop/portal/desktop: unknown error type:
[2023-10-08T21:42:17.919+0000] {docker.py:403} INFO - [13:103:1008/214217.918218:ERROR:bus.cc(406)] Failed to connect to the bus: Failed to connect to socket /var/run/dbus/system_bus_socket: No such file or directory
[13:103:1008/214217.918278:ERROR:bus.cc(406)] Failed to connect to the bus: Failed to connect to socket /var/run/dbus/system_bus_socket: No such file or directory
[2023-10-08T21:42:17.919+0000] {docker.py:403} INFO - [13:103:1008/214217.918569:ERROR:bus.cc(406)] Failed to connect to the bus: Failed to connect to socket /var/run/dbus/system_bus_socket: No such file or directory
[13:103:1008/214217.918651:ERROR:bus.cc(406)] Failed to connect to the bus: Failed to connect to socket /var/run/dbus/system_bus_socket: No such file or directory
[2023-10-08T21:42:17.920+0000] {docker.py:403} INFO - [13:103:1008/214217.918729:ERROR:bus.cc(406)] Failed to connect to the bus: Failed to connect to socket /var/run/dbus/system_bus_socket: No such file or directory
[2023-10-08T21:42:17.987+0000] {docker.py:403} INFO - [74:74:1008/214217.986350:ERROR:viz_main_impl.cc(196)] Exiting GPU process due to errors during initialization
[2023-10-08T21:42:27.697+0000] {docker.py:403} INFO - initialising bot
opening chrome (Linux)
open chrome
[2023-10-08T21:42:27.762+0000] {docker.py:403} INFO - Traceback (most recent call last):
  File "/usr/local/lib/python3.8/dist-packages/urllib3/connection.py", line 203, in _new_conn
    sock = connection.create_connection(
  File "/usr/local/lib/python3.8/dist-packages/urllib3/util/connection.py", line 60, in create_connection
    for res in socket.getaddrinfo(host, port, family, socket.SOCK_STREAM):
  File "/usr/lib/python3.8/socket.py", line 918, in getaddrinfo
    for res in _socket.getaddrinfo(host, port, family, type, proto, flags):
socket.gaierror: [Errno -3] Temporary failure in name resolution

The above exception was the direct cause of the following exception:

Traceback (most recent call last):
  File "/usr/local/lib/python3.8/dist-packages/urllib3/connectionpool.py", line 790, in urlopen
    response = self._make_request(
  File "/usr/local/lib/python3.8/dist-packages/urllib3/connectionpool.py", line 491, in _make_request
    raise new_e
  File "/usr/local/lib/python3.8/dist-packages/urllib3/connectionpool.py", line 467, in _make_request
    self._validate_conn(conn)
  File "/usr/local/lib/python3.8/dist-packages/urllib3/connectionpool.py", line 1092, in _validate_conn
    conn.connect()
  File "/usr/local/lib/python3.8/dist-packages/urllib3/connection.py", line 611, in connect
    self.sock = sock = self._new_conn()
  File "/usr/local/lib/python3.8/dist-packages/urllib3/connection.py", line 210, in _new_conn
    raise NameResolutionError(self.host, self, e) from e
urllib3.exceptions.NameResolutionError: <urllib3.connection.HTTPSConnection object at 0x7f82e7ba1610>: Failed to resolve 'googlechromelabs.github.io' ([Errno -3] Temporary failure in name resolution)

The above exception was the direct cause of the following exception:

Traceback (most recent call last):
  File "/usr/local/lib/python3.8/dist-packages/requests/adapters.py", line 486, in send
    resp = conn.urlopen(
  File "/usr/local/lib/python3.8/dist-packages/urllib3/connectionpool.py", line 844, in urlopen
    retries = retries.increment(
  File "/usr/local/lib/python3.8/dist-packages/urllib3/util/retry.py", line 515, in increment
    raise MaxRetryError(_pool, url, reason) from reason  # type: ignore[arg-type]
urllib3.exceptions.MaxRetryError: HTTPSConnectionPool(host='googlechromelabs.github.io', port=443): Max retries exceeded with url: /chrome-for-testing/latest-patch-versions-per-build.json (Caused by NameResolutionError("<urllib3.connection.HTTPSConnection object at 0x7f82e7ba1610>: Failed to resolve 'googlechromelabs.github.io' ([Errno -3] Temporary failure in name resolution)"))

During handling of the above exception, another exception occurred:

Traceback (most recent call last):
  File "/usr/local/lib/python3.8/dist-packages/webdriver_manager/core/http.py", line 32, in get
    resp = requests.get(
  File "/usr/local/lib/python3.8/dist-packages/requests/api.py", line 73, in get
    return request("get", url, params=params, **kwargs)
  File "/usr/local/lib/python3.8/dist-packages/requests/api.py", line 59, in request
    return session.request(method=method, url=url, **kwargs)
  File "/usr/local/lib/python3.8/dist-packages/requests/sessions.py", line 589, in request
    resp = self.send(prep, **send_kwargs)
  File "/usr/local/lib/python3.8/dist-packages/requests/sessions.py", line 703, in send
    r = adapter.send(request, **kwargs)
  File "/usr/local/lib/python3.8/dist-packages/requests/adapters.py", line 519, in send
    raise ConnectionError(e, request=request)
requests.exceptions.ConnectionError: HTTPSConnectionPool(host='googlechromelabs.github.io', port=443): Max retries exceeded with url: /chrome-for-testing/latest-patch-versions-per-build.json (Caused by NameResolutionError("<urllib3.connection.HTTPSConnection object at 0x7f82e7ba1610>: Failed to resolve 'googlechromelabs.github.io' ([Errno -3] Temporary failure in name resolution)"))

During handling of the above exception, another exception occurred:

Traceback (most recent call last):
  File "webscrape.py", line 149, in <module>
    StackScraper()
  File "webscrape.py", line 15, in __init__
    super().__init__(verbose=True)
  File "/tmp/Bot.py", line 51, in __init__
    self.driver = webdriver.Chrome(service=Service(ChromeDriverManager().install()),options=options)
  File "/usr/local/lib/python3.8/dist-packages/webdriver_manager/chrome.py", line 40, in install
    driver_path = self._get_driver_binary_path(self.driver)
  File "/usr/local/lib/python3.8/dist-packages/webdriver_manager/core/manager.py", line 35, in _get_driver_binary_path
    binary_path = self._cache_manager.find_driver(driver)
  File "/usr/local/lib/python3.8/dist-packages/webdriver_manager/core/driver_cache.py", line 105, in find_driver
    driver_version = self.get_cache_key_driver_version(driver)
  File "/usr/local/lib/python3.8/dist-packages/webdriver_manager/core/driver_cache.py", line 152, in get_cache_key_driver_version
    return driver.get_driver_version_to_download()
  File "/usr/local/lib/python3.8/dist-packages/webdriver_manager/core/driver.py", line 48, in get_driver_version_to_download
    return self.get_latest_release_version()
  File "/usr/local/lib/python3.8/dist-packages/webdriver_manager/drivers/chrome.py", line 59, in get_latest_release_version
    response = self._http_client.get(url)
  File "/usr/local/lib/python3.8/dist-packages/webdriver_manager/core/http.py", line 35, in get
    raise exceptions.ConnectionError(f"Could not reach host. Are you offline?")
requests.exceptions.ConnectionError: Could not reach host. Are you offline?
[2023-10-08T21:42:28.265+0000] {taskinstance.py:1824} ERROR - Task failed with exception
Traceback (most recent call last):
  File "/home/airflow/.local/lib/python3.7/site-packages/docker/api/client.py", line 268, in _raise_for_status
    response.raise_for_status()
  File "/home/airflow/.local/lib/python3.7/site-packages/requests/models.py", line 1021, in raise_for_status
    raise HTTPError(http_error_msg, response=self)
requests.exceptions.HTTPError: 400 Client Error: Bad Request for url: http://docker-proxy:2375/v1.43/containers/create

The above exception was the direct cause of the following exception:

Traceback (most recent call last):
  File "/home/airflow/.local/lib/python3.7/site-packages/airflow/providers/docker/operators/docker.py", line 339, in _run_image
    return self._run_image_with_mounts(self.mounts + [tmp_mount], add_tmp_variable=True)
  File "/home/airflow/.local/lib/python3.7/site-packages/airflow/providers/docker/operators/docker.py", line 393, in _run_image_with_mounts
    hostname=self.hostname,
  File "/home/airflow/.local/lib/python3.7/site-packages/docker/api/container.py", line 431, in create_container
    return self.create_container_from_config(config, name, platform)
  File "/home/airflow/.local/lib/python3.7/site-packages/docker/api/container.py", line 448, in create_container_from_config
    return self._result(res, True)
  File "/home/airflow/.local/lib/python3.7/site-packages/docker/api/client.py", line 274, in _result
    self._raise_for_status(response)
  File "/home/airflow/.local/lib/python3.7/site-packages/docker/api/client.py", line 270, in _raise_for_status
    raise create_api_error_from_http_exception(e) from e
  File "/home/airflow/.local/lib/python3.7/site-packages/docker/errors.py", line 39, in create_api_error_from_http_exception
    raise cls(e, response=response, explanation=explanation) from e
docker.errors.APIError: 400 Client Error for http://docker-proxy:2375/v1.43/containers/create: Bad Request ("invalid mount config for type "bind": bind source path does not exist: /tmp/airflowtmpqw4zp1ar")

During handling of the above exception, another exception occurred:

Traceback (most recent call last):
  File "/home/airflow/.local/lib/python3.7/site-packages/airflow/providers/docker/operators/docker.py", line 478, in execute
    return self._run_image()
  File "/home/airflow/.local/lib/python3.7/site-packages/airflow/providers/docker/operators/docker.py", line 348, in _run_image
    return self._run_image_with_mounts(self.mounts, add_tmp_variable=False)
  File "/home/airflow/.local/lib/python3.7/site-packages/airflow/providers/docker/operators/docker.py", line 412, in _run_image_with_mounts
    raise AirflowException(f"Docker container failed: {repr(result)} lines {joined_log_lines}")
airflow.exceptions.AirflowException: Docker container failed: {'StatusCode': 1} lines [13:60:1008/214217.681363:ERROR:bus.cc(406)] Failed to connect to the bus: Failed to connect to socket /var/run/dbus/system_bus_socket: No such file or directory
[13:64:1008/214217.853438:ERROR:bus.cc(406)] Failed to connect to the bus: Failed to connect to socket /var/run/dbus/system_bus_socket: No such file or directory
[13:64:1008/214217.853514:ERROR:bus.cc(406)] Failed to connect to the bus: Failed to connect to socket /var/run/dbus/system_bus_socket: No such file or directory
[13:60:1008/214217.857145:ERROR:bus.cc(406)] Failed to connect to the bus: Could not parse server address: Unknown address type (examples of valid types are "tcp" and on UNIX "unix")
[13:60:1008/214217.857224:ERROR:bus.cc(406)] Failed to connect to the bus: Could not parse server address: Unknown address type (examples of valid types are "tcp" and on UNIX "unix")
[13:60:1008/214217.857241:ERROR:bus.cc(406)] Failed to connect to the bus: Could not parse server address: Unknown address type (examples of valid types are "tcp" and on UNIX "unix")
[13:60:1008/214217.857250:ERROR:bus.cc(406)] Failed to connect to the bus: Could not parse server address: Unknown address type (examples of valid types are "tcp" and on UNIX "unix")
[13:60:1008/214217.874034:ERROR:bus.cc(406)] Failed to connect to the bus: Could not parse server address: Unknown address type (examples of valid types are "tcp" and on UNIX "unix")
[13:60:1008/214217.874071:ERROR:bus.cc(406)] Failed to connect to the bus: Could not parse server address: Unknown address type (examples of valid types are "tcp" and on UNIX "unix")
DevTools listening on ws://127.0.0.1:4444/devtools/browser/c340d8be-c42e-4fb7-b992-af066ec370fc
[13:13:1008/214217.908514:ERROR:object_proxy.cc(576)] Failed to call method: org.freedesktop.portal.Settings.Read: object_path= /org/freedesktop/portal/desktop: unknown error type:
[13:103:1008/214217.918218:ERROR:bus.cc(406)] Failed to connect to the bus: Failed to connect to socket /var/run/dbus/system_bus_socket: No such file or directory
[13:103:1008/214217.918278:ERROR:bus.cc(406)] Failed to connect to the bus: Failed to connect to socket /var/run/dbus/system_bus_socket: No such file or directory
[13:103:1008/214217.918569:ERROR:bus.cc(406)] Failed to connect to the bus: Failed to connect to socket /var/run/dbus/system_bus_socket: No such file or directory
[13:103:1008/214217.918651:ERROR:bus.cc(406)] Failed to connect to the bus: Failed to connect to socket /var/run/dbus/system_bus_socket: No such file or directory
[13:103:1008/214217.918729:ERROR:bus.cc(406)] Failed to connect to the bus: Failed to connect to socket /var/run/dbus/system_bus_socket: No such file or directory
[74:74:1008/214217.986350:ERROR:viz_main_impl.cc(196)] Exiting GPU process due to errors during initialization
initialising bot
opening chrome (Linux)
open chrome
Traceback (most recent call last):
  File "/usr/local/lib/python3.8/dist-packages/urllib3/connection.py", line 203, in _new_conn
    sock = connection.create_connection(
  File "/usr/local/lib/python3.8/dist-packages/urllib3/util/connection.py", line 60, in create_connection
    for res in socket.getaddrinfo(host, port, family, socket.SOCK_STREAM):
  File "/usr/lib/python3.8/socket.py", line 918, in getaddrinfo
    for res in _socket.getaddrinfo(host, port, family, type, proto, flags):
socket.gaierror: [Errno -3] Temporary failure in name resolution

The above exception was the direct cause of the following exception:

Traceback (most recent call last):
  File "/usr/local/lib/python3.8/dist-packages/urllib3/connectionpool.py", line 790, in urlopen
    response = self._make_request(
  File "/usr/local/lib/python3.8/dist-packages/urllib3/connectionpool.py", line 491, in _make_request
    raise new_e
  File "/usr/local/lib/python3.8/dist-packages/urllib3/connectionpool.py", line 467, in _make_request
    self._validate_conn(conn)
  File "/usr/local/lib/python3.8/dist-packages/urllib3/connectionpool.py", line 1092, in _validate_conn
    conn.connect()
  File "/usr/local/lib/python3.8/dist-packages/urllib3/connection.py", line 611, in connect
    self.sock = sock = self._new_conn()
  File "/usr/local/lib/python3.8/dist-packages/urllib3/connection.py", line 210, in _new_conn
    raise NameResolutionError(self.host, self, e) from e
urllib3.exceptions.NameResolutionError: <urllib3.connection.HTTPSConnection object at 0x7f82e7ba1610>: Failed to resolve 'googlechromelabs.github.io' ([Errno -3] Temporary failure in name resolution)

The above exception was the direct cause of the following exception:

Traceback (most recent call last):
  File "/usr/local/lib/python3.8/dist-packages/requests/adapters.py", line 486, in send
    resp = conn.urlopen(
  File "/usr/local/lib/python3.8/dist-packages/urllib3/connectionpool.py", line 844, in urlopen
    retries = retries.increment(
  File "/usr/local/lib/python3.8/dist-packages/urllib3/util/retry.py", line 515, in increment
    raise MaxRetryError(_pool, url, reason) from reason  # type: ignore[arg-type]
urllib3.exceptions.MaxRetryError: HTTPSConnectionPool(host='googlechromelabs.github.io', port=443): Max retries exceeded with url: /chrome-for-testing/latest-patch-versions-per-build.json (Caused by NameResolutionError("<urllib3.connection.HTTPSConnection object at 0x7f82e7ba1610>: Failed to resolve 'googlechromelabs.github.io' ([Errno -3] Temporary failure in name resolution)"))

During handling of the above exception, another exception occurred:

Traceback (most recent call last):
  File "/usr/local/lib/python3.8/dist-packages/webdriver_manager/core/http.py", line 32, in get
    resp = requests.get(
  File "/usr/local/lib/python3.8/dist-packages/requests/api.py", line 73, in get
    return request("get", url, params=params, **kwargs)
  File "/usr/local/lib/python3.8/dist-packages/requests/api.py", line 59, in request
    return session.request(method=method, url=url, **kwargs)
  File "/usr/local/lib/python3.8/dist-packages/requests/sessions.py", line 589, in request
    resp = self.send(prep, **send_kwargs)
  File "/usr/local/lib/python3.8/dist-packages/requests/sessions.py", line 703, in send
    r = adapter.send(request, **kwargs)
  File "/usr/local/lib/python3.8/dist-packages/requests/adapters.py", line 519, in send
    raise ConnectionError(e, request=request)
requests.exceptions.ConnectionError: HTTPSConnectionPool(host='googlechromelabs.github.io', port=443): Max retries exceeded with url: /chrome-for-testing/latest-patch-versions-per-build.json (Caused by NameResolutionError("<urllib3.connection.HTTPSConnection object at 0x7f82e7ba1610>: Failed to resolve 'googlechromelabs.github.io' ([Errno -3] Temporary failure in name resolution)"))

During handling of the above exception, another exception occurred:

Traceback (most recent call last):
  File "webscrape.py", line 149, in <module>
    StackScraper()
  File "webscrape.py", line 15, in __init__
    super().__init__(verbose=True)
  File "/tmp/Bot.py", line 51, in __init__
    self.driver = webdriver.Chrome(service=Service(ChromeDriverManager().install()),options=options)
  File "/usr/local/lib/python3.8/dist-packages/webdriver_manager/chrome.py", line 40, in install
    driver_path = self._get_driver_binary_path(self.driver)
  File "/usr/local/lib/python3.8/dist-packages/webdriver_manager/core/manager.py", line 35, in _get_driver_binary_path
    binary_path = self._cache_manager.find_driver(driver)
  File "/usr/local/lib/python3.8/dist-packages/webdriver_manager/core/driver_cache.py", line 105, in find_driver
    driver_version = self.get_cache_key_driver_version(driver)
  File "/usr/local/lib/python3.8/dist-packages/webdriver_manager/core/driver_cache.py", line 152, in get_cache_key_driver_version
    return driver.get_driver_version_to_download()
  File "/usr/local/lib/python3.8/dist-packages/webdriver_manager/core/driver.py", line 48, in get_driver_version_to_download
    return self.get_latest_release_version()
  File "/usr/local/lib/python3.8/dist-packages/webdriver_manager/drivers/chrome.py", line 59, in get_latest_release_version
    response = self._http_client.get(url)
  File "/usr/local/lib/python3.8/dist-packages/webdriver_manager/core/http.py", line 35, in get
    raise exceptions.ConnectionError(f"Could not reach host. Are you offline?")
requests.exceptions.ConnectionError: Could not reach host. Are you offline?
[2023-10-08T21:42:28.285+0000] {taskinstance.py:1350} INFO - Marking task as UP_FOR_RETRY. dag_id=Extract_job_data_in_selenium_container, task_id=run_script_in_docker, execution_date=20231008T214214, start_date=20231008T214216, end_date=20231008T214228
[2023-10-08T21:42:28.310+0000] {standard_task_runner.py:109} ERROR - Failed to execute job 521 for task run_script_in_docker (Docker container failed: {'StatusCode': 1} lines [13:60:1008/214217.681363:ERROR:bus.cc(406)] Failed to connect to the bus: Failed to connect to socket /var/run/dbus/system_bus_socket: No such file or directory
[13:64:1008/214217.853438:ERROR:bus.cc(406)] Failed to connect to the bus: Failed to connect to socket /var/run/dbus/system_bus_socket: No such file or directory
[13:64:1008/214217.853514:ERROR:bus.cc(406)] Failed to connect to the bus: Failed to connect to socket /var/run/dbus/system_bus_socket: No such file or directory
[13:60:1008/214217.857145:ERROR:bus.cc(406)] Failed to connect to the bus: Could not parse server address: Unknown address type (examples of valid types are "tcp" and on UNIX "unix")
[13:60:1008/214217.857224:ERROR:bus.cc(406)] Failed to connect to the bus: Could not parse server address: Unknown address type (examples of valid types are "tcp" and on UNIX "unix")
[13:60:1008/214217.857241:ERROR:bus.cc(406)] Failed to connect to the bus: Could not parse server address: Unknown address type (examples of valid types are "tcp" and on UNIX "unix")
[13:60:1008/214217.857250:ERROR:bus.cc(406)] Failed to connect to the bus: Could not parse server address: Unknown address type (examples of valid types are "tcp" and on UNIX "unix")
[13:60:1008/214217.874034:ERROR:bus.cc(406)] Failed to connect to the bus: Could not parse server address: Unknown address type (examples of valid types are "tcp" and on UNIX "unix")
[13:60:1008/214217.874071:ERROR:bus.cc(406)] Failed to connect to the bus: Could not parse server address: Unknown address type (examples of valid types are "tcp" and on UNIX "unix")
DevTools listening on ws://127.0.0.1:4444/devtools/browser/c340d8be-c42e-4fb7-b992-af066ec370fc
[13:13:1008/214217.908514:ERROR:object_proxy.cc(576)] Failed to call method: org.freedesktop.portal.Settings.Read: object_path= /org/freedesktop/portal/desktop: unknown error type:
[13:103:1008/214217.918218:ERROR:bus.cc(406)] Failed to connect to the bus: Failed to connect to socket /var/run/dbus/system_bus_socket: No such file or directory
[13:103:1008/214217.918278:ERROR:bus.cc(406)] Failed to connect to the bus: Failed to connect to socket /var/run/dbus/system_bus_socket: No such file or directory
[13:103:1008/214217.918569:ERROR:bus.cc(406)] Failed to connect to the bus: Failed to connect to socket /var/run/dbus/system_bus_socket: No such file or directory
[13:103:1008/214217.918651:ERROR:bus.cc(406)] Failed to connect to the bus: Failed to connect to socket /var/run/dbus/system_bus_socket: No such file or directory
[13:103:1008/214217.918729:ERROR:bus.cc(406)] Failed to connect to the bus: Failed to connect to socket /var/run/dbus/system_bus_socket: No such file or directory
[74:74:1008/214217.986350:ERROR:viz_main_impl.cc(196)] Exiting GPU process due to errors during initialization
initialising bot
opening chrome (Linux)
open chrome
Traceback (most recent call last):
  File "/usr/local/lib/python3.8/dist-packages/urllib3/connection.py", line 203, in _new_conn
    sock = connection.create_connection(
  File "/usr/local/lib/python3.8/dist-packages/urllib3/util/connection.py", line 60, in create_connection
    for res in socket.getaddrinfo(host, port, family, socket.SOCK_STREAM):
  File "/usr/lib/python3.8/socket.py", line 918, in getaddrinfo
    for res in _socket.getaddrinfo(host, port, family, type, proto, flags):
socket.gaierror: [Errno -3] Temporary failure in name resolution

The above exception was the direct cause of the following exception:

Traceback (most recent call last):
  File "/usr/local/lib/python3.8/dist-packages/urllib3/connectionpool.py", line 790, in urlopen
    response = self._make_request(
  File "/usr/local/lib/python3.8/dist-packages/urllib3/connectionpool.py", line 491, in _make_request
    raise new_e
  File "/usr/local/lib/python3.8/dist-packages/urllib3/connectionpool.py", line 467, in _make_request
    self._validate_conn(conn)
  File "/usr/local/lib/python3.8/dist-packages/urllib3/connectionpool.py", line 1092, in _validate_conn
    conn.connect()
  File "/usr/local/lib/python3.8/dist-packages/urllib3/connection.py", line 611, in connect
    self.sock = sock = self._new_conn()
  File "/usr/local/lib/python3.8/dist-packages/urllib3/connection.py", line 210, in _new_conn
    raise NameResolutionError(self.host, self, e) from e
urllib3.exceptions.NameResolutionError: <urllib3.connection.HTTPSConnection object at 0x7f82e7ba1610>: Failed to resolve 'googlechromelabs.github.io' ([Errno -3] Temporary failure in name resolution)

The above exception was the direct cause of the following exception:

Traceback (most recent call last):
  File "/usr/local/lib/python3.8/dist-packages/requests/adapters.py", line 486, in send
    resp = conn.urlopen(
  File "/usr/local/lib/python3.8/dist-packages/urllib3/connectionpool.py", line 844, in urlopen
    retries = retries.increment(
  File "/usr/local/lib/python3.8/dist-packages/urllib3/util/retry.py", line 515, in increment
    raise MaxRetryError(_pool, url, reason) from reason  # type: ignore[arg-type]
urllib3.exceptions.MaxRetryError: HTTPSConnectionPool(host='googlechromelabs.github.io', port=443): Max retries exceeded with url: /chrome-for-testing/latest-patch-versions-per-build.json (Caused by NameResolutionError("<urllib3.connection.HTTPSConnection object at 0x7f82e7ba1610>: Failed to resolve 'googlechromelabs.github.io' ([Errno -3] Temporary failure in name resolution)"))

During handling of the above exception, another exception occurred:

Traceback (most recent call last):
  File "/usr/local/lib/python3.8/dist-packages/webdriver_manager/core/http.py", line 32, in get
    resp = requests.get(
  File "/usr/local/lib/python3.8/dist-packages/requests/api.py", line 73, in get
    return request("get", url, params=params, **kwargs)
  File "/usr/local/lib/python3.8/dist-packages/requests/api.py", line 59, in request
    return session.request(method=method, url=url, **kwargs)
  File "/usr/local/lib/python3.8/dist-packages/requests/sessions.py", line 589, in request
    resp = self.send(prep, **send_kwargs)
  File "/usr/local/lib/python3.8/dist-packages/requests/sessions.py", line 703, in send
    r = adapter.send(request, **kwargs)
  File "/usr/local/lib/python3.8/dist-packages/requests/adapters.py", line 519, in send
    raise ConnectionError(e, request=request)
requests.exceptions.ConnectionError: HTTPSConnectionPool(host='googlechromelabs.github.io', port=443): Max retries exceeded with url: /chrome-for-testing/latest-patch-versions-per-build.json (Caused by NameResolutionError("<urllib3.connection.HTTPSConnection object at 0x7f82e7ba1610>: Failed to resolve 'googlechromelabs.github.io' ([Errno -3] Temporary failure in name resolution)"))

During handling of the above exception, another exception occurred:

Traceback (most recent call last):
  File "webscrape.py", line 149, in <module>
    StackScraper()
  File "webscrape.py", line 15, in __init__
    super().__init__(verbose=True)
  File "/tmp/Bot.py", line 51, in __init__
    self.driver = webdriver.Chrome(service=Service(ChromeDriverManager().install()),options=options)
  File "/usr/local/lib/python3.8/dist-packages/webdriver_manager/chrome.py", line 40, in install
    driver_path = self._get_driver_binary_path(self.driver)
  File "/usr/local/lib/python3.8/dist-packages/webdriver_manager/core/manager.py", line 35, in _get_driver_binary_path
    binary_path = self._cache_manager.find_driver(driver)
  File "/usr/local/lib/python3.8/dist-packages/webdriver_manager/core/driver_cache.py", line 105, in find_driver
    driver_version = self.get_cache_key_driver_version(driver)
  File "/usr/local/lib/python3.8/dist-packages/webdriver_manager/core/driver_cache.py", line 152, in get_cache_key_driver_version
    return driver.get_driver_version_to_download()
  File "/usr/local/lib/python3.8/dist-packages/webdriver_manager/core/driver.py", line 48, in get_driver_version_to_download
    return self.get_latest_release_version()
  File "/usr/local/lib/python3.8/dist-packages/webdriver_manager/drivers/chrome.py", line 59, in get_latest_release_version
    response = self._http_client.get(url)
  File "/usr/local/lib/python3.8/dist-packages/webdriver_manager/core/http.py", line 35, in get
    raise exceptions.ConnectionError(f"Could not reach host. Are you offline?")
requests.exceptions.ConnectionError: Could not reach host. Are you offline?; 875)
[2023-10-08T21:42:28.352+0000] {local_task_job_runner.py:225} INFO - Task exited with return code 1
[2023-10-08T21:42:28.373+0000] {taskinstance.py:2653} INFO - 0 downstream tasks scheduled from follow-on schedule check
