[2023-10-09T02:19:55.262+0000] {taskinstance.py:1103} INFO - Dependencies all met for dep_context=non-requeueable deps ti=<TaskInstance: Extract_job_data_in_selenium_container.run_script_in_docker manual__2023-10-09T02:19:53.200935+00:00 [queued]>
[2023-10-09T02:19:55.277+0000] {taskinstance.py:1103} INFO - Dependencies all met for dep_context=requeueable deps ti=<TaskInstance: Extract_job_data_in_selenium_container.run_script_in_docker manual__2023-10-09T02:19:53.200935+00:00 [queued]>
[2023-10-09T02:19:55.277+0000] {taskinstance.py:1308} INFO - Starting attempt 1 of 2
[2023-10-09T02:19:55.303+0000] {taskinstance.py:1327} INFO - Executing <Task(DockerOperator): run_script_in_docker> on 2023-10-09 02:19:53.200935+00:00
[2023-10-09T02:19:55.309+0000] {standard_task_runner.py:57} INFO - Started process 238 to run task
[2023-10-09T02:19:55.317+0000] {standard_task_runner.py:84} INFO - Running: ['***', 'tasks', 'run', 'Extract_job_data_in_selenium_container', 'run_script_in_docker', 'manual__2023-10-09T02:19:53.200935+00:00', '--job-id', '625', '--raw', '--subdir', 'DAGS_FOLDER/extract_job_data_dag.py', '--cfg-path', '/tmp/tmpu28avv1q']
[2023-10-09T02:19:55.318+0000] {standard_task_runner.py:85} INFO - Job 625: Subtask run_script_in_docker
[2023-10-09T02:19:55.396+0000] {task_command.py:410} INFO - Running <TaskInstance: Extract_job_data_in_selenium_container.run_script_in_docker manual__2023-10-09T02:19:53.200935+00:00 [running]> on host e12c8be37a23
[2023-10-09T02:19:55.530+0000] {taskinstance.py:1547} INFO - Exporting env vars: AIRFLOW_CTX_DAG_OWNER='***' AIRFLOW_CTX_DAG_ID='Extract_job_data_in_selenium_container' AIRFLOW_CTX_TASK_ID='run_script_in_docker' AIRFLOW_CTX_EXECUTION_DATE='2023-10-09T02:19:53.200935+00:00' AIRFLOW_CTX_TRY_NUMBER='1' AIRFLOW_CTX_DAG_RUN_ID='manual__2023-10-09T02:19:53.200935+00:00'
[2023-10-09T02:19:55.568+0000] {docker.py:334} INFO - Starting docker container from image webscrape-container
[2023-10-09T02:19:55.577+0000] {taskinstance.py:1824} ERROR - Task failed with exception
Traceback (most recent call last):
  File "/home/airflow/.local/lib/python3.7/site-packages/docker/api/client.py", line 268, in _raise_for_status
    response.raise_for_status()
  File "/home/airflow/.local/lib/python3.7/site-packages/requests/models.py", line 1021, in raise_for_status
    raise HTTPError(http_error_msg, response=self)
requests.exceptions.HTTPError: 400 Client Error: Bad Request for url: http://docker-proxy:2375/v1.43/containers/create

The above exception was the direct cause of the following exception:

Traceback (most recent call last):
  File "/home/airflow/.local/lib/python3.7/site-packages/airflow/providers/docker/operators/docker.py", line 478, in execute
    return self._run_image()
  File "/home/airflow/.local/lib/python3.7/site-packages/airflow/providers/docker/operators/docker.py", line 339, in _run_image
    return self._run_image_with_mounts(self.mounts + [tmp_mount], add_tmp_variable=True)
  File "/home/airflow/.local/lib/python3.7/site-packages/airflow/providers/docker/operators/docker.py", line 393, in _run_image_with_mounts
    hostname=self.hostname,
  File "/home/airflow/.local/lib/python3.7/site-packages/docker/api/container.py", line 431, in create_container
    return self.create_container_from_config(config, name, platform)
  File "/home/airflow/.local/lib/python3.7/site-packages/docker/api/container.py", line 448, in create_container_from_config
    return self._result(res, True)
  File "/home/airflow/.local/lib/python3.7/site-packages/docker/api/client.py", line 274, in _result
    self._raise_for_status(response)
  File "/home/airflow/.local/lib/python3.7/site-packages/docker/api/client.py", line 270, in _raise_for_status
    raise create_api_error_from_http_exception(e) from e
  File "/home/airflow/.local/lib/python3.7/site-packages/docker/errors.py", line 39, in create_api_error_from_http_exception
    raise cls(e, response=response, explanation=explanation) from e
docker.errors.APIError: 400 Client Error for http://docker-proxy:2375/v1.43/containers/create: Bad Request ("invalid mount config for type "bind": bind source path does not exist: /opt/airflow/extraction")
[2023-10-09T02:19:55.588+0000] {taskinstance.py:1350} INFO - Marking task as UP_FOR_RETRY. dag_id=Extract_job_data_in_selenium_container, task_id=run_script_in_docker, execution_date=20231009T021953, start_date=20231009T021955, end_date=20231009T021955
[2023-10-09T02:19:55.609+0000] {standard_task_runner.py:109} ERROR - Failed to execute job 625 for task run_script_in_docker (400 Client Error for http://docker-proxy:2375/v1.43/containers/create: Bad Request ("invalid mount config for type "bind": bind source path does not exist: /opt/airflow/extraction"); 238)
[2023-10-09T02:19:55.654+0000] {local_task_job_runner.py:225} INFO - Task exited with return code 1
[2023-10-09T02:19:55.679+0000] {taskinstance.py:2653} INFO - 0 downstream tasks scheduled from follow-on schedule check
